Traceback (most recent call last):
  File "/usr/lib64/python3.6/site-packages/numpy/core/__init__.py", line 16, in <module>
    from . import multiarray
ImportError: libopenblasp.so.0: cannot open shared object file: No such file or directory

During handling of the above exception, another exception occurred:

Traceback (most recent call last):
  File "python/test_data_loader.py", line 8, in <module>
    import numpy as np
  File "/usr/lib64/python3.6/site-packages/numpy/__init__.py", line 142, in <module>
    from . import add_newdocs
  File "/usr/lib64/python3.6/site-packages/numpy/add_newdocs.py", line 13, in <module>
    from numpy.lib import add_newdoc
  File "/usr/lib64/python3.6/site-packages/numpy/lib/__init__.py", line 8, in <module>
    from .type_check import *
  File "/usr/lib64/python3.6/site-packages/numpy/lib/type_check.py", line 11, in <module>
    import numpy.core.numeric as _nx
  File "/usr/lib64/python3.6/site-packages/numpy/core/__init__.py", line 26, in <module>
    raise ImportError(msg)
ImportError: 
Importing the multiarray numpy extension module failed.  Most
likely you are trying to import a failed build of numpy.
If you're working with a numpy git repo, try `git clean -xdf` (removes all
files not under version control).  Otherwise reinstall numpy.

Original error was: libopenblasp.so.0: cannot open shared object file: No such file or directory

